<?xml version="1.0"?>
<robot name="rover">
    <link name="body">
        <visual>
            <origin xyz="0 0 0" rpy="0 -0 0" />
            <geometry>
                <mesh filename="package://rover_ gz_description/meshes/body.stl"/>
            </geometry>
            <material name="body_material">
                <color rgba="0.80000000000000004441 0.80000000000000004441 0.80000000000000004441 1.0"/>
            </material>
        </visual>
        <collision>
            <origin xyz="0 0 0" rpy="0 -0 0" />
            <geometry>
                <mesh filename="package://rover_ gz_description/meshes/body.stl"/>
            </geometry>
        </collision>
        <inertial>
            <origin xyz="0.037500001962775565689 0.025384343231719459777 0.02252413516897633014" rpy="0 0 0"/>
            <mass value="2.2387448144601149735" />
            <inertia ixx="0.0020602257937801194895" ixy="4.4849745952044535794e-10"  ixz="6.4700580511958914472e-11" iyy="0.0015069060220098920867" iyz="-0.00028761045332653629525" izz="0.0025435366954411004273" />
        </inertial>
    </link>

    <link name="wheel">
        <visual>
            <origin xyz="-0.03250000000000000111 0.024999999999999997918 -0.020000000000000000416" rpy="1.570796326794896558 1.570796326794896558 0" />
            <geometry>
                <mesh filename="package://rover_ gz_description/meshes/wheel.stl"/>
            </geometry>
            <material name="wheel_material">
                <color rgba="0.26274509803921569651 0.28235294117647058432 0.30196078431372547213 1.0"/>
            </material>
        </visual>
        <collision>
            <origin xyz="-0.03250000000000000111 0.024999999999999997918 -0.020000000000000000416" rpy="1.570796326794896558 1.570796326794896558 0" />
            <geometry>
                <mesh filename="package://rover_ gz_description/meshes/wheel.stl"/>
            </geometry>
        </collision>
        <inertial>
            <origin xyz="0 0 -0.0040000000000000000833" rpy="0 0 0"/>
            <mass value="0.33541920259867763487" />
            <inertia ixx="0.0001743668705176219802" ixy="0"  ixz="0" iyy="0.00017436687051762189888" iyz="0" izz="0.00034529842223087294558" />
        </inertial>
    </link>

    <joint name="wheel1_speed" type="revolute">
        <origin xyz="-0.020000000000000000416 0.03250000000000000111 0.024999999999999997918" rpy="-1.570796326794896558 -0 1.570796326794896558" />
        <parent link="body" />
        <child link="wheel" />
        <axis xyz="0 0 1"/>
        <limit effort="1" velocity="20" />
        <joint_properties friction="0.0"/>
    </joint>

    <link name="wheel_2">
        <visual>
            <origin xyz="-0.032499999999999994171 0.024999999999999997918 -0.01199999999999999678" rpy="1.570796326794896558 1.570796326794896558 0" />
            <geometry>
                <mesh filename="package://rover_ gz_description/meshes/wheel.stl"/>
            </geometry>
            <material name="wheel_material">
                <color rgba="0.26274509803921569651 0.28235294117647058432 0.30196078431372547213 1.0"/>
            </material>
        </visual>
        <collision>
            <origin xyz="-0.032499999999999994171 0.024999999999999997918 -0.01199999999999999678" rpy="1.570796326794896558 1.570796326794896558 0" />
            <geometry>
                <mesh filename="package://rover_ gz_description/meshes/wheel.stl"/>
            </geometry>
        </collision>
        <inertial>
            <origin xyz="6.9388939039072283776e-18 0 0.0040000000000000035527" rpy="0 0 0"/>
            <mass value="0.33541920259867763487" />
            <inertia ixx="0.0001743668705176219802" ixy="0"  ixz="0" iyy="0.00017436687051762189888" iyz="0" izz="0.00034529842223087294558" />
        </inertial>
    </link>

    <joint name="wheel2_speed" type="revolute">
        <origin xyz="0.09500000000000000111 0.032499999999999994171 0.024999999999999994449" rpy="-1.570796326794896558 -0 1.570796326794896558" />
        <parent link="body" />
        <child link="wheel_2" />
        <axis xyz="0 0 1"/>
        <limit effort="1" velocity="20" />
        <joint_properties friction="0.0"/>
    </joint>

  <gazebo>
    <plugin name="two_wheeled_robot_diff_drive" filename="libgazebo_ros_diff_drive.so">
      <update_rate>100</update_rate>

      <left_joint>wheel1_speed</left_joint>
      <right_joint>wheel2_speed</right_joint>

      <wheel_separation>0.14022037</wheel_separation>
      <wheel_diameter>0.033</wheel_diameter>

      <max_wheel_torque>20.0</max_wheel_torque>
      <max_wheel_acceleration>20.0</max_wheel_acceleration>

      <command_topic>cmd_vel</command_topic>

      <publish_odom>true</publish_odom>
      <publish_odom_tf>true</publish_odom_tf>
      <publish_wheel_tf>true</publish_wheel_tf>
      
      <odometry_topic>odom</odometry_topic>
      <odometry_frame>odom_link</odometry_frame>
      <robot_base_frame>body</robot_base_frame>

      <odometry_source>1</odometry_source>
      <ros>
        <remapping>odom:=wheel/odometry</remapping>
      </ros>
    </plugin>
  </gazebo>

  <gazebo>
    <plugin name="gazebo_ros_joint_state_publisher" filename="libgazebo_ros_joint_state_publisher.so">
      <update_rate>100</update_rate>
      <joint_name>caster_front_joint</joint_name>
      <joint_name>caster_rear_joint</joint_name>
    </plugin>
  </gazebo>

</robot>
